
Random seeds have been fixed as 42


Standard Output/Error are going to be logged in the followings: 
  - ./ripples/define_ripples/using_CNN/plots_3d_scatter/log/stdout.log
  - ./ripples/define_ripples/using_CNN/plots_3d_scatter/log/stderr.log


Matplotilb has been configured as follows:
{'figure.figsize': (16.2, 10), 'font.size': 20, 'legend.fontsize': 'small', 'pdf.fonttype': 42, 'ps.fonttype': 42}.


Random seeds have been fixed as 42

Traceback (most recent call last):
  File "/usr/local/lib64/python3.8/site-packages/pandas/core/indexes/base.py", line 3080, in get_loc
    return self._engine.get_loc(casted_key)
  File "pandas/_libs/index.pyx", line 70, in pandas._libs.index.IndexEngine.get_loc
  File "pandas/_libs/index.pyx", line 101, in pandas._libs.index.IndexEngine.get_loc
  File "pandas/_libs/hashtable_class_helper.pxi", line 4554, in pandas._libs.hashtable.PyObjectHashTable.get_item
  File "pandas/_libs/hashtable_class_helper.pxi", line 4562, in pandas._libs.hashtable.PyObjectHashTable.get_item
KeyError: 'are_ripple_CNN'

The above exception was the direct cause of the following exception:

Traceback (most recent call last):
  File "./ripples/define_ripples/using_CNN/plots_3d_scatter.py", line 48, in <module>
    are_ripple_CNN = rips_df["are_ripple_CNN"]
  File "/usr/local/lib64/python3.8/site-packages/pandas/core/frame.py", line 3024, in __getitem__
    indexer = self.columns.get_loc(key)
  File "/usr/local/lib64/python3.8/site-packages/pandas/core/indexes/base.py", line 3082, in get_loc
    raise KeyError(key) from err
KeyError: 'are_ripple_CNN'

Random seeds have been fixed as 42


Standard Output/Error are going to be logged in the followings: 
  - ./ripples/define_ripples/using_CNN/plots_3d_scatter/log/stdout.log
  - ./ripples/define_ripples/using_CNN/plots_3d_scatter/log/stderr.log


Matplotilb has been configured as follows:
{'figure.figsize': (16.2, 10), 'font.size': 20, 'legend.fontsize': 'small', 'pdf.fonttype': 42, 'ps.fonttype': 42}.


Random seeds have been fixed as 42

Traceback (most recent call last):
  File "/usr/local/lib64/python3.8/site-packages/pandas/core/indexes/base.py", line 3080, in get_loc
    return self._engine.get_loc(casted_key)
  File "pandas/_libs/index.pyx", line 70, in pandas._libs.index.IndexEngine.get_loc
  File "pandas/_libs/index.pyx", line 101, in pandas._libs.index.IndexEngine.get_loc
  File "pandas/_libs/hashtable_class_helper.pxi", line 4554, in pandas._libs.hashtable.PyObjectHashTable.get_item
  File "pandas/_libs/hashtable_class_helper.pxi", line 4562, in pandas._libs.hashtable.PyObjectHashTable.get_item
KeyError: 'are_ripple_CNN'

The above exception was the direct cause of the following exception:

Traceback (most recent call last):
  File "./ripples/define_ripples/using_CNN/plots_3d_scatter.py", line 48, in <module>
    are_ripple_CNN = rips_df["are_ripple_CNN"]
  File "/usr/local/lib64/python3.8/site-packages/pandas/core/frame.py", line 3024, in __getitem__
    indexer = self.columns.get_loc(key)
  File "/usr/local/lib64/python3.8/site-packages/pandas/core/indexes/base.py", line 3082, in get_loc
    raise KeyError(key) from err
KeyError: 'are_ripple_CNN'
